<?xml version="1.0" ?>
<!-- =================================================================================== -->
<!-- |    This document was autogenerated by xacro from al5d_gazebo.xacro              | -->
<!-- |    EDITING THIS FILE BY HAND IS NOT RECOMMENDED                                 | -->
<!-- =================================================================================== -->
<robot name="al5d" xmlns:xacro="http://ros.org/wiki/xacro">
  <link name="base">
    <visual>
      <origin rpy="0 0 0" xyz="0 0 0.0215"/>
      <geometry>
        <cylinder length="0.043" radius="0.048"/>
      </geometry>
      <material name="black">
        <color rgba="0 0 0 0.85"/>
      </material>
    </visual>
    <collision>
      <origin rpy="0 0 0" xyz="0 0 0.0215"/>
      <geometry>
        <cylinder length="0.043" radius="0.048"/>
      </geometry>
    </collision>
    <inertial>
      <mass value="0.3"/>
      <inertia ixx="0.001" ixy="0.0" ixz="0.0" iyy="0.001" iyz="0.0" izz="0.001"/>
    </inertial>
  </link>
  <link name="upper_base">
    <visual>
      <origin rpy="0 0 0" xyz="0 0 0"/>
      <geometry>
        <cylinder length="0.006" radius="0.048"/>
      </geometry>
      <material name="black">
        </material>
    </visual>
    <collision>
      <origin rpy="0 0 0" xyz="0 0 0"/>
      <geometry>
        <cylinder length="0.006" radius="0.048"/>
      </geometry>
    </collision>
    <inertial>
      <mass value="0.3"/>
      <inertia ixx="0.001" ixy="0.0" ixz="0.0" iyy="0.001" iyz="0.0" izz="0.001"/>
    </inertial>
  </link>
  <link name="upper_arm">
    <visual>
      <origin rpy="0 0 0" xyz="0.073025 0 0"/>
      <geometry>
        <box size="0.14605 0.05 0.05"/>
      </geometry>
      <material name="silver">
        <color rgba="0.8 0.8 0.8 0.85"/>
      </material>
    </visual>
    <collision>
      <origin rpy="0 0 0" xyz="0.073025 0 0"/>
      <geometry>
        <box size="0.14605 0.05 0.05"/>
      </geometry>
    </collision>
    <inertial>
      <mass value="0.3"/>
      <inertia ixx="0.001" ixy="0.0" ixz="0.0" iyy="0.001" iyz="0.0" izz="0.001"/>
    </inertial>
  </link>
  <link name="lower_arm">
    <visual>
      <origin rpy="0 0 0" xyz="0.0936625 0 0"/>
      <geometry>
        <box size="0.187325 0.035 0.035"/>
      </geometry>
      <material name="blue">
        <color rgba="0.4 0.4 1 0.85"/>
      </material>
    </visual>
    <collision>
      <origin rpy="0 0 0" xyz="0.0936625 0 0"/>
      <geometry>
        <box size="0.187325 0.035 0.035"/>
      </geometry>
    </collision>
    <inertial>
      <mass value="0.3"/>
      <inertia ixx="0.001" ixy="0.0" ixz="0.0" iyy="0.001" iyz="0.0" izz="0.001"/>
    </inertial>
  </link>
  <link name="wrist">
    <visual>
      <origin rpy="0 0 0" xyz="0.0275 0 0"/>
      <geometry>
        <box size="0.055 0.025 0.025"/>
      </geometry>
      <material name="silver">
        </material>
    </visual>
    <collision>
      <origin rpy="0 0 0" xyz="0.0275 0 0"/>
      <geometry>
        <box size="0.055 0.025 0.025"/>
      </geometry>
    </collision>
    <inertial>
      <mass value="0.3"/>
      <inertia ixx="0.001" ixy="0.0" ixz="0.0" iyy="0.001" iyz="0.0" izz="0.001"/>
    </inertial>
  </link>
  <link name="gripper_base">
    <visual>
      <origin rpy="0 0 0" xyz="0.01 0 0"/>
      <geometry>
        <box size="0.02 0.02 0.05"/>
      </geometry>
      <material name="red">
        <color rgba="1 0.3 0.3 0.85"/>
      </material>
    </visual>
    <collision>
      <origin rpy="0 0 0" xyz="0.025 0 0"/>
      <geometry>
        <box size="0.02 0.02 0.05"/>
      </geometry>
    </collision>
    <inertial>
      <mass value="0.3"/>
      <inertia ixx="0.001" ixy="0.0" ixz="0.0" iyy="0.001" iyz="0.0" izz="0.001"/>
    </inertial>
  </link>
  <link name="gripper_dummy">
    <visual>
      <origin rpy="0 0 0" xyz="0 0 0"/>
    </visual>
  </link>
  <link name="gripper_rightfinger">
    <visual>
      <origin rpy="0 0 0" xyz="0.02 0 0"/>
      <geometry>
        <box size="0.04 0.02 0.02"/>
      </geometry>
      <material name="red">
        <color rgba="1 0.3 0.3 0.85"/>
      </material>
    </visual>
    <collision>
      <origin rpy="0 0 0" xyz="0.025 0 0"/>
      <geometry>
        <box size="0.05 0.02 0.02"/>
      </geometry>
    </collision>
    <inertial>
      <mass value="0.3"/>
      <inertia ixx="0.001" ixy="0.0" ixz="0.0" iyy="0.001" iyz="0.0" izz="0.001"/>
    </inertial>
  </link>
  <link name="gripper_leftfinger">
    <visual>
      <origin rpy="0 0 0" xyz="0.02 0 0"/>
      <geometry>
        <box size="0.04 0.02 0.02"/>
      </geometry>
      <material name="red">
        <color rgba="1 0.3 0.3 0.85"/>
      </material>
    </visual>
    <collision>
      <origin rpy="0 0 0" xyz="0.025 0 0"/>
      <geometry>
        <box size="0.05 0.02 0.02"/>
      </geometry>
    </collision>
    <inertial>
      <mass value="0.3"/>
      <inertia ixx="0.001" ixy="0.0" ixz="0.0" iyy="0.001" iyz="0.0" izz="0.001"/>
    </inertial>
  </link>
  <link name="end">
    </link>
  <!-- joints -->
  <joint name="base_rotate" type="revolute">
    <origin rpy="0 0 0" xyz="0 0 0.049"/>
    <parent link="base"/>
    <child link="upper_base"/>
    <axis xyz="0 0 1"/>
    <limit effort="0" lower="-1.570795" upper="1.570795" velocity="3.67"/>
  </joint>
  <joint name="shoulder_tilt" type="revolute">
    <origin rpy="1.570795 -1.570795 0 " xyz="0 0 0.022"/>
    <parent link="upper_base"/>
    <child link="upper_arm"/>
    <axis xyz="0 0 1"/>
    <limit effort="0" lower="-1.570795" upper="1.570795" velocity="3.32"/>
  </joint>
  <joint name="elbow_tilt" type="revolute">
    <origin rpy="0 0 -1.570795" xyz="0.14605 0 0"/>
    <parent link="upper_arm"/>
    <child link="lower_arm"/>
    <axis xyz="0 0 1"/>
    <limit effort="0" lower="-1.570795" upper="1.570795" velocity="3.67"/>
  </joint>
  <joint name="wrist_tilt" type="revolute">
    <origin rpy="0 0 0" xyz="0.187325 0 0"/>
    <parent link="lower_arm"/>
    <child link="wrist"/>
    <axis xyz="0 0 1"/>
    <limit effort="0" lower="-1.570795" upper="1.570795" velocity="6.98"/>
  </joint>
  <joint name="wrist_rotate" type="revolute">
    <origin rpy="0 0 0" xyz="0.055 0 0"/>
    <parent link="wrist"/>
    <child link="gripper_base"/>
    <axis xyz="1 0 0"/>
    <limit effort="0" lower="-1.570795" upper="1.570795" velocity="6.98"/>
  </joint>
  <joint name="open_gripper" type="prismatic">
    <origin rpy="0 0 0" xyz="0.02 0 0.01"/>
    <parent link="gripper_base"/>
    <child link="gripper_dummy"/>
    <axis xyz="0 0 1"/>
    <limit effort="0" lower="0" upper="1.570795" velocity="6.98"/>
  </joint>
  <joint name="open_gripperright" type="prismatic">
    <origin rpy="0 0 0" xyz="0.02 0 0.01"/>
    <parent link="gripper_base"/>
    <child link="gripper_rightfinger"/>
    <axis xyz="0 0 1"/>
    <mimic joint="open_gripper" multiplier="0.00636620310098" offset="0"/>
    <limit effort="0" lower="0" upper="0.015" velocity="6.98"/>
  </joint>
  <joint name="open_gripperleft" type="prismatic">
    <origin rpy="0 0 0" xyz="0.02 0 -0.01"/>
    <parent link="gripper_base"/>
    <child link="gripper_leftfinger"/>
    <axis xyz="0 0 1"/>
    <mimic joint="open_gripper" multiplier="-0.00636620310098" offset="0"/>
    <limit effort="0" lower="0" upper="0.015" velocity="6.98"/>
  </joint>
  <joint name="end" type="fixed">
    <origin rpy="0 0 0" xyz="0.055 0 0"/>
    <parent link="gripper_base"/>
    <child link="end"/>
  </joint>
  <!-- plugins -->
  <gazebo>
    <plugin filename="libgazebo_ros_joint_pose_trajectory.so" name="al5d_controller">
      <topicName>/joint_controller/command</topicName>
      <updateRate>0.01</updateRate>
    </plugin>
  </gazebo>
</robot>

